Workbook

Sheet Cover
C1: Bill of Quantities Package - Ancillary Trades
C2: ES26-081 | Lon Eilian, Caernarfon | Beech Developments
A4: DISCLAIMER: This information is supplied in good faith for guidance and coordination only. It is not part of the Nudura ICF price and must be checked and verified by the appropriate professional (quantity surveyor, designer, engineer or supplier) before use. Only the Nudura ICF formwork and associated accessories are included in our price. Quantities are measured from the quotation model and drawings; no allowance for waste is included unless stated. Plot C/D is the handed mirror of Plot A/B; quantities match except Bill 6. Rates and amounts are by others.
A6: Project | B6: Lon Eilian, Caernarfon
A7: Site | B7: Lon Eilian, Caernarfon, Gwynedd
A8: Client | B8: Beech Developments
A9: Quotation ref | B9: ES26-081
A10: Document | B10: Bill of Quantities Package - Ancillary Trades
A11: Issue | B11: 01 (19/10/2026)
A12: Scope | B12: 4 x 2B1P flats - one pair of semi-detached buildings: Plot A/B and Plot C/D (each = GF flat + FF flat)
A13: Prepared by | B13: BuildEase (Tremco CPG UK) - BuildEase Design Suite quotation model
A14: Status | B14: FOR INFORMATION, COORDINATION AND PRICING BY OTHERS - rates blank; NOT part of the Nudura ICF price
A16: PACKAGE OVERVIEW - pricing by others (all amounts formula-linked to each bill's Package Summary)
A17: Bill | B17: Package | C17: Code / NRM2 | D17: Supply £ | E17: Install £ | F17: Total £
A18: Bill 1 | B18: Substructure & Frame - ICF Concrete Core | C18: FRM NRM2 11 | D18: ='Bill 1 Concrete Core'!I20 | E18: ='Bill 1 Concrete Core'!J20 | F18: ='Bill 1 Concrete Core'!K20
A19: Bill 2 | B19: External Wall Finishes - Render, Brick Slips & Beads | C19: CLD NRM2 21, 28 | D19: ='Bill 2 External Finishes'!I39 | E19: ='Bill 2 External Finishes'!J39 | F19: ='Bill 2 External Finishes'!K39
A20: Bill 3 | B20: Internal Linings - Plasterboard, Tape, Beads & Skim | C20: DRY NRM2 28 | D20: ='Bill 3 Internal Linings'!I42 | E20: ='Bill 3 Internal Linings'!J42 | F20: ='Bill 3 Internal Linings'!K42
A21: Bill 4 | B21: Internal Doors & Ironmongery | C21: JOI NRM2 24 | D21: ='Bill 4 Doors'!I38 | E21: ='Bill 4 Doors'!J38 | F21: ='Bill 4 Doors'!K38
A22: Bill 5 | B22: Joinery - Skirtings, Architraves & Window Boards | C22: JOI NRM2 22 | D22: ='Bill 5 Joinery'!I48 | E22: ='Bill 5 Joinery'!J48 | F22: ='Bill 5 Joinery'!K48
A23: Bill 6 | B23: Timber Stud Partitions - Framing, Openings, Pattresses & Fixings | C23: JOI NRM2 16 | D23: ='Bill 6 Partitions'!I51 | E23: ='Bill 6 Partitions'!J51 | F23: ='Bill 6 Partitions'!K51
A24: GRAND TOTAL - ancillary trades, net (excl. VAT) | D24: =SUM(D18:D23) | E24: =SUM(E18:E23) | F24: =SUM(F18:F23)
A26: Optional additions (enter %; blank = 0) | C26: % | F26: Amount £
A27: Preliminaries | B27: on the net grand total | F27: =(F24)*N(C27)
A28: Overheads & profit | B28: on net total + preliminaries | F28: =(F24+F27)*N(C28)
A29: Contingency | B29: on net total + preliminaries + OH&P | F29: =(F24+F27+F28)*N(C29)
A30: GRAND TOTAL including preliminaries, OH&P and contingency (excl. VAT) | F30: =F24+F27+F28+F29
A31: Pale-yellow cells are the only inputs (rates on each bill sheet, percentages here). Everything else is a locked formula (protection has no password). Schedules A and B are reference only and are not priced.
A33: IMPORTANT - This information is supplied in good faith for guidance and coordination only. It is not part of the Nudura ICF price and must be checked and verified by the appropriate professional (quantity surveyor, designer, engineer or supplier) before use. Only the Nudura ICF formwork and associated accessories are included in our price. Quantities are measured from the quotation model and drawings; no allowance for waste is included unless stated. Plot C/D is the handed mirror of Plot A/B; quantities match except Bill 6. Rates and amounts are by others.
A35: KEY QUANTITIES (both plots, net; linked to the bills)
A36: Concrete core (whole building) | D36: ='Bill 1 Concrete Core'!F9+'Bill 1 Concrete Core'!F10+'Bill 1 Concrete Core'!F11 | E36: m3
A37: Render, Dryvit (walls, excl. reveals) | D37: ='Bill 2 External Finishes'!F9+'Bill 2 External Finishes'!F10+'Bill 2 External Finishes'!F11 | E37: m2
A38: Brick slips, Monolith (walls, excl. reveals) | D38: ='Bill 2 External Finishes'!F15+'Bill 2 External Finishes'!F16+'Bill 2 External Finishes'!F17+'Bill 2 External Finishes'!F18 | E38: m2
A39: Plasterboard, walls and reveals (net) | D39: ='Bill 3 Internal Linings'!F9+'Bill 3 Internal Linings'!F10+'Bill 3 Internal Linings'!F11+'Bill 3 Internal Linings'!F12+'Bill 3 Internal Linings'!F13+'Bill 3 Internal Linings'!F14+'Bill 3 Internal Linings'!F15+'Bill 3 Internal Linings'!F16+'Bill 3 Internal Linings'!F17+'Bill 3 Internal Linings'!F18+'Bill 3 Internal Linings'!F19+'Bill 3 Internal Linings'!F20 | E39: m2
A40: Plasterboard, ceilings (net area) | D40: ='Bill 3 Internal Linings'!F23+'Bill 3 Internal Linings'!F24+'Bill 3 Internal Linings'!F25+'Bill 3 Internal Linings'!F26 | E40: m2
A41: Skim coat | D41: ='Bill 3 Internal Linings'!F33 | E41: m2
A42: Internal doorsets | D42: ='Bill 4 Doors'!F9+'Bill 4 Doors'!F10+'Bill 4 Doors'!F11+'Bill 4 Doors'!F12+'Bill 4 Doors'!F13+'Bill 4 Doors'!F14+'Bill 4 Doors'!F15+'Bill 4 Doors'!F16+'Bill 4 Doors'!F17+'Bill 4 Doors'!F18+'Bill 4 Doors'!F19+'Bill 4 Doors'!F20 | E42: nr
A43: Skirting | D43: ='Bill 5 Joinery'!F24 | E43: m
A44: Architrave | D44: ='Bill 5 Joinery'!F27+'Bill 5 Joinery'!F28 | E44: m
A45: Window boards | D45: ='Bill 5 Joinery'!F31+'Bill 5 Joinery'!F32+'Bill 5 Joinery'!F33+'Bill 5 Joinery'!F34+'Bill 5 Joinery'!F35+'Bill 5 Joinery'!F36+'Bill 5 Joinery'!F37+'Bill 5 Joinery'!F38+'Bill 5 Joinery'!F39+'Bill 5 Joinery'!F40 | E45: nr
A46: Window boards, total length | D46: ='Bill 5 Joinery'!F41 | E46: m
...

Sheet General Notes
B1: General Notes, Measurement Basis, Assumptions & Exclusions
B2: ES26-081 | Lon Eilian, Caernarfon | Beech Developments
A4: DISCLAIMER: This information is supplied in good faith for guidance and coordination only. It is not part of the Nudura ICF price and must be checked and verified by the appropriate professional (quantity surveyor, designer, engineer or supplier) before use. Only the Nudura ICF formwork and associated accessories are included in our price. Quantities are measured from the quotation model and drawings; no allowance for waste is included unless stated. Plot C/D is the handed mirror of Plot A/B; quantities match except Bill 6. Rates and amounts are by others.
A6: 1 Purpose and status
A7: 1.1 | B7: This package presents the ancillary-trade quantities measured by BuildEase alongside the Nudura ICF quotation for Lon Eilian, Caernarfon (ref ES26-081). It is set out in the form of a Bill of Quantities so that the client, their quantity surveyor and trade contractors can price and coordinate the works.
A8: 1.2 | B8: Status: FOR INFORMATION, COORDINATION AND PRICING BY OTHERS. Supply and install rates are left blank deliberately - BuildEase / Tremco CPG are not pricing these trades. The Excel workbook is a live pricing document: enter rates and every amount, section subtotal, package total and the cover overview update by formula.
A9: 1.3 | B9: This information is supplied in good faith for guidance and coordination only. It is not part of the Nudura ICF price and must be checked and verified by the appropriate professional (quantity surveyor, designer, engineer or supplier) before use. Only the Nudura ICF formwork and associated accessories are included in our price.
A10: 1.4 | B10: Quantities are measured from the quotation model and drawings; no allowance for waste is included unless stated. Plot C/D is the handed mirror of Plot A/B; quantities match except Bill 6. Rates and amounts are by others.
A12: 2 Basis of measurement
A13: 2.1 | B13: Measured generally in accordance with the principles of NRM2 (RICS New Rules of Measurement, Detailed measurement for building works): work measured net as fixed in position, items grouped by work section, units m / m2 / m3 / nr / item. NRM2 is referenced for structure only; descriptions are BuildEase's own.
A14: 2.2 | B14: Quantities are NET. No allowance for waste, laps, cutting or breakage is included unless stated. Where useful an "Order guide" with a stated waste % is given in the Notes column; it is guidance only.
A15: 2.3 | B15: Quantities are given to two decimal places and are not rounded to whole units. Per-plot columns: Plot A/B (GF flat + FF flat) and Plot C/D (GF flat + FF flat). Plot C/D is the handed mirror of Plot A/B; quantities match except Bill 6.
A16: 2.4 | B16: Sources: drawing P1361-LEC-SAL-02-ZZ-DR-A-0007 P2 (2B1P flat plans and elevations, vector, 1:100 @ A2); site elevations 0005 P04 for the porch lean-to; the BuildEase quotation model (structural openings, wall set-out, timber partitions and internal doors); the model concrete core (04_Logs/build/core.json); for Bill 6 the TLSTF timber-frame model extract (construction_data.json, drawings ES26-081-TF-01 / TF-02), 04_Logs/specs/LE_partitions.json and the LEP2 partition build reports.
A17: 2.5 | B17: Bills 1 to 5 are generated from the Extra Info take-off of 16/10/2026 (le_xi_takeoff.py) and are identical to it; this package only re-presents them. Bill 6 (timber stud partitions) is measured from the TLSTF model extract of 19/10/2026 and agrees with the timber schedules on the TF sheets.
A19: 3 Assumptions
A20: 3.1 | B20: Walls: external ICF 6in XR35 (355.6 mm overall); party and stair-enclosure walls 6in Standard (285.75 mm). ICF concrete core 152.4 mm.
A21: 3.2 | B21: Windows / doors set 1/3 back from the outer ICF face (118.5 mm). External reveal = set-back + finish (render 10 mm / slips 25 mm). Internal reveal = 195 mm (ICF less set-back less frame 70 plus lining 27.5).
A22: 3.3 | B22: Heights: GF walls FFL 0 to underside of FF joists 2575; FF walls from 2850 to ceiling under truss bottom chords (2450). Floor zone 2,575-2,850 excluded except the stair-well band.
A23: 3.4 | B23: Render: Dryvit direct-applied over ICF EPS. Brick slips: Monolith system. Both are proposals to be confirmed with the suppliers.
A24: 3.5 | B24: Plasterboard: 12.5 mm wallboard to ICF faces (MR in bathrooms); 15 mm Type F fire board to party and stair-enclosure walls; 15 mm each side of 38 x 89 stud partitions; GF ceiling (separating floor) 2 x 15 mm fire / acoustic board on resilient bars; FF ceilings 12.5 mm plus VCL.
A25: 3.6 | B25: Doors: 1,210 mm gaps taken as cupboard pairs. Under-stair store door FD30S self-closing as a precaution. Flat entrance doors open to outside (PAS 24 / SBD, not FD30S).
A26: 3.7 | B26: Concrete core: net from the model; order guide +5%, 6 m3 truck mixers, 60 m3 per pump per day, one pour per form level.
A28: 4 Exclusions (not measured in this package)
A29: 4.1 | B29: Nudura ICF formwork and accessories (in the Nudura price - see section 6).
A30: 4.2 | B30: Supply of windows and external doorsets, external cills (listed for coordination only), roof coverings, soffits, fascias and rainwater goods.
A31: 4.3 | B31: Floor finishes and screeds, decorations, staircases and balustrades, kitchens, sanitaryware, M&E services and builder's work.
A32: 4.4 | B32: Reinforcement design and scheduling, concrete mix design, temporary works, scaffolding and access, preliminaries, waste removal, VAT.
A33: 4.5 | B33: Fire-stopping, cavity barriers, insulation to partitions and floors, sealants and mastics, except where expressly described.
A35: 5 Items to be confirmed
A36: 5.1 | B36: Room areas match the drawn schedule within 0.05 m2 except: GF store 3.24 m2 on plan vs 2.9 drawn (headroom); GF stair lobby 3.05 vs 2.5 drawn; FF hall 6.88 m2 excluding the stair void vs 10.5 drawn (incl. void and landing). See Schedule A.
A37: 5.2 | B37: Porch / stair-lobby side walls are not on the 0007 elevations; taken as brick slip from the site side elevation (trapezoid 2,360 rising at 23 deg).
A38: 5.3 | B38: 1,210 mm door gaps (G6 GF hall to A/C, F9 FF A/C) taken as cupboard pairs.
A39: 5.4 | B39: FD30S to the under-stair store door is a precaution - confirm with Building Control.
A40: 5.5 | B40: Board types and the Dryvit / Monolith build-ups are proposals - confirm with the suppliers and the designer.
A41: 5.6 | B41: Concrete mix, reinforcement and pour sequence to the structural engineer.
A43: 6 What IS in the Nudura price (Quotation ES26-081 Rev A)
A44: 6.1 | B44: Nudura pre-cut ICF kit for Plots A, B, C and D as modelled in the BuildEase Design Suite.
A45: 6.2 | B45: Accessories: VJC clips, fibre tape, protective tape, spray foam, Form Lock and T-junction straps.
A46: 6.3 | B46: BuildEase Pre-Cut Service: design, coordination, installation drawings, pre-cutting and packaging of forms, field services support.
A47: 6.4 | B47: Alignment: 4 stillages of alignment systems for 4 weeks. Haulage: estimate, to be confirmed on the agreed build sequence.
...

Sheet Summary of Bills
C1: Summary of Bills - section breakdown
C2: ES26-081 | Lon Eilian, Caernarfon | Beech Developments - amounts by others, excl. VAT
A4: DISCLAIMER: This information is supplied in good faith for guidance and coordination only. It is not part of the Nudura ICF price and must be checked and verified by the appropriate professional (quantity surveyor, designer, engineer or supplier) before use. Only the Nudura ICF formwork and associated accessories are included in our price. Quantities are measured from the quotation model and drawings; no allowance for waste is included unless stated. Plot C/D is the handed mirror of Plot A/B; quantities match except Bill 6. Rates and amounts are by others.
A6: Bill | B6: Section | C6: Description | D6: Supply £ | E6: Install £ | F6: Total £
A7: 1 | B7: 1A | C7: In-situ concrete to ICF wall cores (NRM2 11 / package FRM) | D7: ='Bill 1 Concrete Core'!I18 | E7: ='Bill 1 Concrete Core'!J18 | F7: ='Bill 1 Concrete Core'!K18
A8: 1 | B8: 1B | C8: Reinforcement and associated items (to engineer's design - not measured) | D8: ='Bill 1 Concrete Core'!I19 | E8: ='Bill 1 Concrete Core'!J19 | F8: ='Bill 1 Concrete Core'!K19
A9: Bill 1 - Substructure & Frame - ICF Concrete Core (package FRM) | D9: ='Bill 1 Concrete Core'!I20 | E9: ='Bill 1 Concrete Core'!J20 | F9: ='Bill 1 Concrete Core'!K20
A10: 2 | B10: 2A | C10: Thin-coat render system over ICF (NRM2 28 / package CLD) | D10: ='Bill 2 External Finishes'!I35 | E10: ='Bill 2 External Finishes'!J35 | F10: ='Bill 2 External Finishes'!K35
A11: 2 | B11: 2B | C11: Brick slip system over ICF (NRM2 21 / package CLD) | D11: ='Bill 2 External Finishes'!I36 | E11: ='Bill 2 External Finishes'!J36 | F11: ='Bill 2 External Finishes'!K36
A12: 2 | B12: 2C | C12: Render beads and trims (NRM2 28 / package CLD) | D12: ='Bill 2 External Finishes'!I37 | E12: ='Bill 2 External Finishes'!J37 | F12: ='Bill 2 External Finishes'!K37
A13: 2 | B13: 2D | C13: Coordination items (supply by others) | D13: ='Bill 2 External Finishes'!I38 | E13: ='Bill 2 External Finishes'!J38 | F13: ='Bill 2 External Finishes'!K38
A14: Bill 2 - External Wall Finishes - Render, Brick Slips & Beads (package CLD) | D14: ='Bill 2 External Finishes'!I39 | E14: ='Bill 2 External Finishes'!J39 | F14: ='Bill 2 External Finishes'!K39
A15: 3 | B15: 3A | C15: Plasterboard wall linings (NRM2 28 / package DRY) | D15: ='Bill 3 Internal Linings'!I39 | E15: ='Bill 3 Internal Linings'!J39 | F15: ='Bill 3 Internal Linings'!K39
A16: 3 | B16: 3B | C16: Plasterboard ceilings (NRM2 28 / package DRY) | D16: ='Bill 3 Internal Linings'!I40 | E16: ='Bill 3 Internal Linings'!J40 | F16: ='Bill 3 Internal Linings'!K40
A17: 3 | B17: 3C | C17: Jointing, beads and skim (NRM2 28 / package DRY) | D17: ='Bill 3 Internal Linings'!I41 | E17: ='Bill 3 Internal Linings'!J41 | F17: ='Bill 3 Internal Linings'!K41
A18: Bill 3 - Internal Linings - Plasterboard, Tape, Beads & Skim (package DRY) | D18: ='Bill 3 Internal Linings'!I42 | E18: ='Bill 3 Internal Linings'!J42 | F18: ='Bill 3 Internal Linings'!K42
A19: 4 | B19: 4A | C19: Internal doorsets (NRM2 24 / package JOI) | D19: ='Bill 4 Doors'!I35 | E19: ='Bill 4 Doors'!J35 | F19: ='Bill 4 Doors'!K35
A20: 4 | B20: 4B | C20: Ironmongery (NRM2 24 / package JOI) | D20: ='Bill 4 Doors'!I36 | E20: ='Bill 4 Doors'!J36 | F20: ='Bill 4 Doors'!K36
A21: 4 | B21: 4C | C21: External doorsets (for information - supply by others) | D21: ='Bill 4 Doors'!I37 | E21: ='Bill 4 Doors'!J37 | F21: ='Bill 4 Doors'!K37
A22: Bill 4 - Internal Doors & Ironmongery (package JOI) | D22: ='Bill 4 Doors'!I38 | E22: ='Bill 4 Doors'!J38 | F22: ='Bill 4 Doors'!K38
A23: 5 | B23: 5A | C23: Skirtings (NRM2 22 / package JOI) | D23: ='Bill 5 Joinery'!I45 | E23: ='Bill 5 Joinery'!J45 | F23: ='Bill 5 Joinery'!K45
A24: 5 | B24: 5B | C24: Architraves (NRM2 22 / package JOI) | D24: ='Bill 5 Joinery'!I46 | E24: ='Bill 5 Joinery'!J46 | F24: ='Bill 5 Joinery'!K46
A25: 5 | B25: 5C | C25: Window boards (NRM2 22 / package JOI) | D25: ='Bill 5 Joinery'!I47 | E25: ='Bill 5 Joinery'!J47 | F25: ='Bill 5 Joinery'!K47
A26: Bill 5 - Joinery - Skirtings, Architraves & Window Boards (package JOI) | D26: ='Bill 5 Joinery'!I48 | E26: ='Bill 5 Joinery'!J48 | F26: ='Bill 5 Joinery'!K48
A27: 6 | B27: 6A | C27: Timber stud partitions, non-loadbearing - framing (NRM2 16 / package JOI) | D27: ='Bill 6 Partitions'!I46 | E27: ='Bill 6 Partitions'!J46 | F27: ='Bill 6 Partitions'!K46
A28: 6 | B28: 6B | C28: Partition timber - supply by section and grade (NRM2 16 / package JOI) | D28: ='Bill 6 Partitions'!I47 | E28: ='Bill 6 Partitions'!J47 | F28: ='Bill 6 Partitions'!K47
A29: 6 | B29: 6C | C29: Forming door openings in partitions (NRM2 16 / package JOI) | D29: ='Bill 6 Partitions'!I48 | E29: ='Bill 6 Partitions'!J48 | F29: ='Bill 6 Partitions'!K48
A30: 6 | B30: 6D | C30: Pattresses, noggins to floor and roof structure, head restraint (NRM2 16 / package JOI) | D30: ='Bill 6 Partitions'!I49 | E30: ='Bill 6 Partitions'!J49 | F30: ='Bill 6 Partitions'!K49
A31: 6 | B31: 6E | C31: Fixings and sundries (NRM2 16 / package JOI) | D31: ='Bill 6 Partitions'!I50 | E31: ='Bill 6 Partitions'!J50 | F31: ='Bill 6 Partitions'!K50
A32: Bill 6 - Timber Stud Partitions - Framing, Openings, Pattresses & Fixings (package JOI) | D32: ='Bill 6 Partitions'!I51 | E32: ='Bill 6 Partitions'!J51 | F32: ='Bill 6 Partitions'!K51
A33: TOTAL - ancillary trades, net (agrees with the Cover overview) | D33: =D9+D14+D18+D22+D26+D32 | E33: =E9+E14+E18+E22+E26+E32 | F33: =F9+F14+F18+F22+F26+F32
A35: Schedule A (Floor Areas) and Schedule B (Structural Openings) are reference schedules and are not priced. Preliminaries, overheads & profit and contingency are applied on the Cover.

Sheet Bill 1 Concrete Core
C1: Bill 1 - Substructure & Frame - ICF Concrete Core
C2: Concrete and reinforcement to fill the Nudura ICF walls. The Nudura price covers the formwork only - concrete, reinforcement and pumping are by others. [NRM2 11 / package FRM]
A4: DISCLAIMER: This information is supplied in good faith for guidance and coordination only. It is not part of the Nudura ICF price and must be checked and verified by the appropriate professional (quantity surveyor, designer, engineer or supplier) before use. Only the Nudura ICF formwork and associated accessories are included in our price. Quantities are measured from the quotation model and drawings; no allowance for waste is included unless stated. Plot C/D is the handed mirror of Plot A/B; quantities match except Bill 6. Rates and amounts are by others.
A6: Ref | B6: Description | C6: Unit | D6: Plot A/B | E6: Plot C/D | F6: Total qty | G6: Supply rate £ | H6: Install rate £ | I6: Supply £ | J6: Install £ | K6: Line total £ | L6: Notes
A7: 1A In-situ concrete to ICF wall cores (NRM2 11 / package FRM)
B8: Ready-mixed concrete placed by pump into Nudura ICF formwork, 152.4 mm (6") core. Mix to the structural engineer's design (typically C25/30, 10 mm max aggregate, S4 slump - confirm). Quantities are net volumes from the model: each wall element envelope x its core band, less opening end caps, lintels and porch-steel pockets. Whole building (both plots poured as one structure on the shared party wall) - per-plot columns not applicable.
A9: 1A.1 | B9: Concrete core: Foundation ICF (FB), 2 courses to GF FFL | C9: m3 | F9: 10.43 | I9: =F9*G9 | J9: =F9*H9 | K9: =I9+J9 | L9: Order guide +5% = 11.0 m3; 2 x 6 m3 loads; 1 pump day
A10: 1A.2 | B10: Concrete core: Ground floor walls (L1) to 2,743, incl. stair enclosure and porch lobby | C10: m3 | F10: 25.45 | I10: =F10*G10 | J10: =F10*H10 | K10: =I10+J10 | L10: Order guide +5% = 26.7 m3; 5 x 6 m3 loads; 1 pump day
A11: 1A.3 | B11: Concrete core: First floor walls (L2) to eaves 5,250, gables to roof line, party wall to rafter line | C11: m3 | F11: 26.36 | I11: =F11*G11 | J11: =F11*H11 | K11: =I11+J11 | L11: Order guide +5% = 27.7 m3; 5 x 6 m3 loads; 1 pump day
A12: 1B Reinforcement and associated items (to engineer's design - not measured)
A13: 1B.1 | B13: Steel reinforcement to ICF wall cores, bars/links/laps to the structural engineer's schedule | C13: item | I13: =IF(ISNUMBER(F13),F13,1)*G13 | J13: =IF(ISNUMBER(F13),F13,1)*H13 | K13: =I13+J13 | L13: Lump sum - the rate entered is the amount. Not measured - no engineer's design at quotation stage
A14: 1B.2 | B14: Concrete pump hire, set-up and line (one visit per pour level, 3 levels) | C14: item | I14: =IF(ISNUMBER(F14),F14,1)*G14 | J14: =IF(ISNUMBER(F14),F14,1)*H14 | K14: =I14+J14 | L14: Lump sum - the rate entered is the amount. Guide: 60 m3 per pump per day; 3 pump visits
A16: PACKAGE SUMMARY - Bill 1 Substructure & Frame - ICF Concrete Core (package FRM; amounts by others, excl. VAT)
A17: Section | B17: Description | I17: Supply £ | J17: Install £ | K17: Total £
A18: 1A | B18: In-situ concrete to ICF wall cores (NRM2 11 / package FRM) | I18: =SUM(I8:I11) | J18: =SUM(J8:J11) | K18: =SUM(K8:K11)
A19: 1B | B19: Reinforcement and associated items (to engineer's design - not measured) | I19: =SUM(I13:I14) | J19: =SUM(J13:J14) | K19: =SUM(K13:K14)
A20: PACKAGE TOTAL - Bill 1, carried to the Cover overview | I20: =SUM(I18:I19) | J20: =SUM(J18:J19) | K20: =SUM(K18:K19)
A21: Pale-yellow cells are the only inputs (Supply rate, Install rate). Amounts, subtotals and totals are formulas; the sheet is protected without a password (Review > Unprotect Sheet). Amounts exclude VAT and are NOT part of the Nudura ICF price.

Sheet Bill 2 External Finishes
C1: Bill 2 - External Wall Finishes - Render, Brick Slips & Beads
C2: Finishes applied to the outer face of the ICF walls, measured net of openings from the drawn elevations. [NRM2 21, 28 / package CLD]
A4: DISCLAIMER: This information is supplied in good faith for guidance and coordination only. It is not part of the Nudura ICF price and must be checked and verified by the appropriate professional (quantity surveyor, designer, engineer or supplier) before use. Only the Nudura ICF formwork and associated accessories are included in our price. Quantities are measured from the quotation model and drawings; no allowance for waste is included unless stated. Plot C/D is the handed mirror of Plot A/B; quantities match except Bill 6. Rates and amounts are by others.
A6: Ref | B6: Description | C6: Unit | D6: Plot A/B | E6: Plot C/D | F6: Total qty | G6: Supply rate £ | H6: Install rate £ | I6: Supply £ | J6: Install £ | K6: Line total £ | L6: Notes
A7: 2A Thin-coat render system over ICF (NRM2 28 / package CLD)
B8: Dryvit direct-applied finish over the ICF EPS face: rasp/level EPS, Dryvit Genesis (or Primus) base coat with Dryvit Standard Mesh, Dryvit primer and textured finish (e.g. Sandpebble / Quarzputz), approx. 10 mm. Measured net of openings as drawn; build-up to be confirmed with Dryvit / Tremco technical for the ICF substrate.
A9: 2A.1 | B9: Render to walls: Front (main + stair-lobby front) elevation | C9: m2 | D9: 16.295 | E9: 16.295 | F9: =D9+E9 | I9: =F9*G9 | J9: =F9*H9 | K9: =I9+J9 | L9: Order guide +10% = 35.9
A10: 2A.2 | B10: Render to walls: Rear elevation | C10: m2 | D10: 33.213 | E10: 33.213 | F10: =D10+E10 | I10: =F10*G10 | J10: =F10*H10 | K10: =I10+J10 | L10: Order guide +10% = 73.1
A11: 2A.3 | B11: Render to walls: Gable (side) elevation | C11: m2 | D11: 24.671 | E11: 24.671 | F11: =D11+E11 | I11: =F11*G11 | J11: =F11*H11 | K11: =I11+J11 | L11: Order guide +10% = 54.3
A12: 2A.4 | B12: Render to reveal returns, jambs and heads, 129 mm girth | C12: m2 | D12: 5.125 | E12: 5.125 | F12: =D12+E12 | I12: =F12*G12 | J12: =F12*H12 | K12: =I12+J12 | L12: Order guide +10% = 11.3
A13: 2B Brick slip system over ICF (NRM2 21 / package CLD)
B14: Monolith brick slip system, adhesive-fixed slips on reinforced base coat over the ICF EPS (or rail / board fixed). Product and fixing to be confirmed with Monolith.
A15: 2B.1 | B15: Brick slips to walls: Front (main + stair-lobby front) elevation | C15: m2 | D15: 18.221 | E15: 18.221 | F15: =D15+E15 | I15: =F15*G15 | J15: =F15*H15 | K15: =I15+J15 | L15: Order guide +10% = 40.1
A16: 2B.2 | B16: Brick slips to walls: Rear elevation | C16: m2 | D16: 6.947 | E16: 6.947 | F16: =D16+E16 | I16: =F16*G16 | J16: =F16*H16 | K16: =I16+J16 | L16: Order guide +10% = 15.3
A17: 2B.3 | B17: Brick slips to walls: Gable (side) elevation | C17: m2 | D17: 18.473 | E17: 18.473 | F17: =D17+E17 | I17: =F17*G17 | J17: =F17*H17 | K17: =I17+J17 | L17: Order guide +10% = 40.6
A18: 2B.4 | B18: Brick slips to walls: Stair-lobby side wall (porch, site side elev.) elevation | C18: m2 | D18: 3.829 | E18: 3.829 | F18: =D18+E18 | I18: =F18*G18 | J18: =F18*H18 | K18: =I18+J18 | L18: Order guide +10% = 8.4; trapezoid from site side elevation (not on 0007)
A19: 2B.5 | B19: Brick slips to reveal returns, jambs and heads, 144 mm girth | C19: m2 | D19: 3.285 | E19: 3.285 | F19: =D19+E19 | I19: =F19*G19 | J19: =F19*H19 | K19: =I19+J19 | L19: Order guide +10% = 7.2
A20: 2B.6 | B20: Brick slip corner slips, building corners | C20: m | D20: 7.57 | E20: 7.57 | F20: =D20+E20 | I20: =F20*G20 | J20: =F20*H20 | K20: =I20+J20 | L20: Order guide +5% = 15.9
A21: 2B.7 | B21: Brick slip corner slips, reveals jambs and heads in slip zones | C21: m | D21: 22.89 | E21: 22.89 | F21: =D21+E21 | I21: =F21*G21 | J21: =F21*H21 | K21: =I21+J21 | L21: Order guide +5% = 48.1
A22: 2B.8 | B22: Brick slip base support / starter | C22: m | D22: 40.111 | E22: 40.111 | F22: =D22+E22 | I22: =F22*G22 | J22: =F22*H22 | K22: =I22+J22 | L22: Order guide +10% = 88.2
A23: 2C Render beads and trims (NRM2 28 / package CLD)
A24: 2C.1 | B24: Render base / starter track | C24: m | D24: 15.72 | E24: 15.72 | F24: =D24+E24 | I24: =F24*G24 | J24: =F24*H24 | K24: =I24+J24 | L24: Order guide +10% = 34.6
A25: 2C.2 | B25: Render stop bead at render / slip junction | C25: m | D25: 37.75 | E25: 37.75 | F25: =D25+E25 | I25: =F25*G25 | J25: =F25*H25 | K25: =I25+J25 | L25: Order guide +10% = 83.1
A26: 2C.3 | B26: Render stop bead under eaves / verge / lean-to | C26: m | D26: 29.14 | E26: 29.14 | F26: =D26+E26 | I26: =F26*G26 | J26: =F26*H26 | K26: =I26+J26 | L26: Order guide +10% = 64.1
A27: 2C.4 | B27: Render stop bead, other edges | C27: m | D27: 14.62 | E27: 14.62 | F27: =D27+E27 | I27: =F27*G27 | J27: =F27*H27 | K27: =I27+J27 | L27: Order guide +10% = 32.2
A28: 2C.5 | B28: Render external corner bead | C28: m | D28: 5.1 | E28: 5.1 | F28: =D28+E28 | I28: =F28*G28 | J28: =F28*H28 | K28: =I28+J28 | L28: Order guide +10% = 11.2
A29: 2C.6 | B29: Render reveal bead, jambs and heads in render | C29: m | D29: 39.87 | E29: 39.87 | F29: =D29+E29 | I29: =F29*G29 | J29: =F29*H29 | K29: =I29+J29 | L29: Order guide +10% = 87.7
A30: 2D Coordination items (supply by others)
A31: 2D.1 | B31: External window cills, measured at window width (for coordination with the window package) | C31: m | D31: 14.24 | E31: 14.24 | F31: =D31+E31 | I31: =F31*G31 | J31: =F31*H31 | K31: =I31+J31 | L31: By window supplier - quantity for coordination only
A33: PACKAGE SUMMARY - Bill 2 External Wall Finishes - Render, Brick Slips & Beads (package CLD; amounts by others, excl. VAT)
A34: Section | B34: Description | I34: Supply £ | J34: Install £ | K34: Total £
A35: 2A | B35: Thin-coat render system over ICF (NRM2 28 / package CLD) | I35: =SUM(I8:I12) | J35: =SUM(J8:J12) | K35: =SUM(K8:K12)
A36: 2B | B36: Brick slip system over ICF (NRM2 21 / package CLD) | I36: =SUM(I14:I22) | J36: =SUM(J14:J22) | K36: =SUM(K14:K22)
A37: 2C | B37: Render beads and trims (NRM2 28 / package CLD) | I37: =SUM(I24:I29) | J37: =SUM(J24:J29) | K37: =SUM(K24:K29)
A38: 2D | B38: Coordination items (supply by others) | I38: =SUM(I31:I31) | J38: =SUM(J31:J31) | K38: =SUM(K31:K31)
A39: PACKAGE TOTAL - Bill 2, carried to the Cover overview | I39: =SUM(I35:I38) | J39: =SUM(J35:J38) | K39: =SUM(K35:K38)
A40: Pale-yellow cells are the only inputs (Supply rate, Install rate). Amounts, subtotals and totals are formulas; the sheet is protected without a password (Review > Unprotect Sheet). Amounts exclude VAT and are NOT part of the Nudura ICF price.

Sheet Bill 3 Internal Linings
C1: Bill 3 - Internal Linings - Plasterboard, Tape, Beads & Skim
C2: Dry linings to the inside faces of the ICF walls, partitions, ceilings and reveals. [NRM2 28 / package DRY]
A4: DISCLAIMER: This information is supplied in good faith for guidance and coordination only. It is not part of the Nudura ICF price and must be checked and verified by the appropriate professional (quantity surveyor, designer, engineer or supplier) before use. Only the Nudura ICF formwork and associated accessories are included in our price. Quantities are measured from the quotation model and drawings; no allowance for waste is included unless stated. Plot C/D is the handed mirror of Plot A/B; quantities match except Bill 6. Rates and amounts are by others.
A6: Ref | B6: Description | C6: Unit | D6: Plot A/B | E6: Plot C/D | F6: Total qty | G6: Supply rate £ | H6: Install rate £ | I6: Supply £ | J6: Install £ | K6: Line total £ | L6: Notes
A7: 3A Plasterboard wall linings (NRM2 28 / package DRY)
B8: Measured net (openings deducted) on the finished faces, per plot (GF flat + FF flat). Floor zone 2,575-2,850 excluded except the stair-well band. Board types are proposals - confirm with the board supplier; ICF faces need mechanical fixings.
A9: 3A.1 | B9: GF external walls - internal face (ICF): 12.5 mm wallboard, screw-fixed to ICF web strips / dabs + mech. fixings (MR board in bathroom) | C9: m2 | D9: 47.416 | E9: 47.416 | F9: =D9+E9 | I9: =F9*G9 | J9: =F9*H9 | K9: =I9+J9 | L9: perimeter 23.89 m x 2.575 m; excludes floor zone 2,575-2,850; layers 1
A10: 3A.2 | B10: GF party wall - this flat side: 15 mm fire-rated (Type F) board on dabs/battens | C10: m2 | D10: 18.617 | E10: 18.617 | F10: =D10+E10 | I10: =F10*G10 | J10: =F10*H10 | K10: =I10+J10 | L10: 7.23 m x 2.575; layers 1
A11: 3A.3 | B11: GF stair-enclosure walls (6in Std) - both faces: 15 mm fire-rated (Type F) board | C11: m2 | D11: 28.098 | E11: 28.098 | F11: =D11+E11 | I11: =F11*G11 | J11: =F11*H11 | K11: =I11+J11 | L11: 12.38 m (all room faces) x 2.575; W_c door deducted both faces; layers 1
A12: 3A.4 | B12: GF timber partitions - both faces: 15 mm board on 38x89 studs (per LE_partitions build-up); MR in bathroom | C12: m2 | D12: 67.78 | E12: 67.78 | F12: =D12+E12 | I12: =F12*G12 | J12: =F12*H12 | K12: =I12+J12 | L12: 34.07 m of room faces x 2.575; layers 1
A13: 3A.5 | B13: GF riser boxing - room face: 12.5 mm MR board on 38x47 | C13: m2 | D13: 2.575 | E13: 2.575 | F13: =D13+E13 | I13: =F13*G13 | J13: =F13*H13 | K13: =I13+J13 | L13: 1.00 m x 2.575; layers 1
A14: 3A.6 | B14: FF external walls - internal face (ICF): 12.5 mm wallboard, screw-fixed to ICF web strips / dabs + mech. fixings (MR board in bathroom) | C14: m2 | D14: 45.297 | E14: 45.297 | F14: =D14+E14 | I14: =F14*G14 | J14: =F14*H14 | K14: =I14+J14 | L14: perimeter 22.21 m x 2.450 m; excludes floor zone 2,575-2,850; layers 1
A15: 3A.7 | B15: FF party wall - this flat side: 15 mm fire-rated (Type F) board on dabs/battens | C15: m2 | D15: 13.745 | E15: 13.745 | F15: =D15+E15 | I15: =F15*G15 | J15: =F15*H15 | K15: =I15+J15 | L15: 5.61 m x 2.450; layers 1
A16: 3A.8 | B16: FF stair-enclosure walls (6in Std) - both faces: 15 mm fire-rated (Type F) board | C16: m2 | D16: 23.716 | E16: 23.716 | F16: =D16+E16 | I16: =F16*G16 | J16: =F16*H16 | K16: =I16+J16 | L16: 9.68 m (all room faces) x 2.450; W_c door deducted both faces; layers 1
A17: 3A.9 | B17: FF timber partitions - both faces: 15 mm board on 38x89 studs (per LE_partitions build-up); MR in bathroom | C17: m2 | D17: 63.214 | E17: 63.214 | F17: =D17+E17 | I17: =F17*G17 | J17: =F17*H17 | K17: =I17+J17 | L17: 34.99 m of room faces x 2.450; layers 1
A18: 3A.10 | B18: FF riser boxing - room face: 12.5 mm MR board on 38x47 | C18: m2 | D18: 2.45 | E18: 2.45 | F18: =D18+E18 | I18: =F18*G18 | J18: =F18*H18 | K18: =I18+J18 | L18: 1.00 m x 2.450; layers 1
A19: 3A.11 | B19: Stair-well floor-zone band (2,575-2,850): 15 mm fire-rated board | C19: m2 | D19: 1.273 | E19: 1.273 | F19: =D19+E19 | I19: =F19*G19 | J19: =F19*H19 | K19: =I19+J19 | L19: W_a + party + front faces of the void x 275; layers 1
A20: 3A.12 | B20: Internal reveals (jambs + heads, ext. openings): 12.5 mm board / bonding + skim | C20: m2 | D20: 12.211 | E20: 12.211 | F20: =D20+E20 | I20: =F20*G20 | J20: =F20*H20 | K20: =I20+J20 | L20: 62.76 m x 195 mm; layers 1
A21: 3B Plasterboard ceilings (NRM2 28 / package DRY)
B22: GF ceiling is the separating floor between the GF and FF flats (60 min fire + acoustic, ADB / ADE): 2 layers. Quantities are net areas of ceiling; multiply by layers for board.
A23: 3B.1 | B23: GF ceilings (u/s FF separating floor): 2 x 15 mm fire/acoustic board (e.g. SoundBloc/FireLine) on resilient bars - separating floor GF/FF flat | C23: m2 | D23: 45.53 | E23: 45.53 | F23: =D23+E23 | I23: =F23*G23 | J23: =F23*H23 | K23: =I23+J23 | L23: GF flat rooms; stair foot is under the FF stair-well (in FF ceiling); layers 2 (board 182.1 m2)
A24: 3B.2 | B24: GF store ceiling = stair soffit: 2 x 15 mm fire-rated (60 min soffit to FF flat stair over GF flat) | C24: m2 | D24: 3.24 | E24: 3.24 | F24: =D24+E24 | I24: =F24*G24 | J24: =F24*H24 | K24: =I24+J24 | L24: plan area; layers 2 (board 13.0 m2)
A25: 3B.3 | B25: GF stair-lobby ceiling (u/s lean-to): 12.5 mm board under lean-to rafters | C25: m2 | D25: 2.094 | E25: 2.094 | F25: =D25+E25 | I25: =F25*G25 | J25: =F25*H25 | K25: =I25+J25 | L25: lobby 1,460 x 1,320 on slope 23 deg; layers 1 (board 4.2 m2)
A26: 3B.4 | B26: FF ceilings (u/s trusses ~5,300): 12.5 mm board + VCL (15 mm Type F if BCO requires) under bottom chords | C26: m2 | D26: 49.81 | E26: 49.81 | F26: =D26+E26 | I26: =F26*G26 | J26: =F26*H26 | K26: =I26+J26 | L26: incl. stair-well void area; layers 1 (board 99.6 m2)
A27: 3C Jointing, beads and skim (NRM2 28 / package DRY)
A28: 3C.1 | B28: Scrim tape, board joints | C28: m | D28: 397.835 | E28: 397.835 | F28: =D28+E28 | I28: =F28*G28 | J28: =F28*H28 | K28: =I28+J28 | L28: Order guide +10% = 875.2
A29: 3C.2 | B29: Scrim tape, internal angles wall-wall | C29: m | D29: 183.6 | E29: 183.6 | F29: =D29+E29 | I29: =F29*G29 | J29: =F29*H29 | K29: =I29+J29 | L29: Order guide +10% = 403.9
A30: 3C.3 | B30: Scrim tape, wall-ceiling angles | C30: m | D30: 152.01 | E30: 152.01 | F30: =D30+E30 | I30: =F30*G30 | J30: =F30*H30 | K30: =I30+J30 | L30: Order guide +10% = 334.4
A31: 3C.4 | B31: Corner bead, external corners in rooms | C31: m | D31: 32.6 | E31: 32.6 | F31: =D31+E31 | I31: =F31*G31 | J31: =F31*H31 | K31: =I31+J31 | L31: Order guide +10% = 71.7
A32: 3C.5 | B32: Corner bead, window/door reveals | C32: m | D32: 62.76 | E32: 62.76 | F32: =D32+E32 | I32: =F32*G32 | J32: =F32*H32 | K32: =I32+J32 | L32: Order guide +10% = 138.1
A33: 3C.6 | B33: Skim coat; skim to all net wall, reveal and ceiling faces | C33: m2 | D33: 427.065 | E33: 427.065 | F33: =D33+E33 | I33: =F33*G33 | J33: =F33*H33 | K33: =I33+J33 | L33: Face layer only
A34: 3D Ordering guide (not a measured item)
A35: 3D.1 | B35: Plasterboard to purchase, all types, including second ceiling layers, before waste | C35: m2 | D35: 475.835 | E35: 475.835 | F35: =D35+E35 | K35: not priced | L35: Order guide +10% = 1,046.8 (guide only)
A37: PACKAGE SUMMARY - Bill 3 Internal Linings - Plasterboard, Tape, Beads & Skim (package DRY; amounts by others, excl. VAT)
A38: Section | B38: Description | I38: Supply £ | J38: Install £ | K38: Total £
A39: 3A | B39: Plasterboard wall linings (NRM2 28 / package DRY) | I39: =SUM(I8:I20) | J39: =SUM(J8:J20) | K39: =SUM(K8:K20)
A40: 3B | B40: Plasterboard ceilings (NRM2 28 / package DRY) | I40: =SUM(I22:I26) | J40: =SUM(J22:J26) | K40: =SUM(K22:K26)
A41: 3C | B41: Jointing, beads and skim (NRM2 28 / package DRY) | I41: =SUM(I28:I33) | J41: =SUM(J28:J33) | K41: =SUM(K28:K33)
A42: PACKAGE TOTAL - Bill 3, carried to the Cover overview | I42: =SUM(I39:I41) | J42: =SUM(J39:J41) | K42: =SUM(K39:K41)
A43: Pale-yellow cells are the only inputs (Supply rate, Install rate). Amounts, subtotals and totals are formulas; the sheet is protected without a password (Review > Unprotect Sheet). Amounts exclude VAT and are NOT part of the Nudura ICF price.

Sheet Bill 4 Doors
C1: Bill 4 - Internal Doors & Ironmongery
C2: Internal doorsets and ironmongery per plot; external doorsets listed for coordination only. [NRM2 24 / package JOI]
A4: DISCLAIMER: This information is supplied in good faith for guidance and coordination only. It is not part of the Nudura ICF price and must be checked and verified by the appropriate professional (quantity surveyor, designer, engineer or supplier) before use. Only the Nudura ICF formwork and associated accessories are included in our price. Quantities are measured from the quotation model and drawings; no allowance for waste is included unless stated. Plot C/D is the handed mirror of Plot A/B; quantities match except Bill 6. Rates and amounts are by others.
A6: Ref | B6: Description | C6: Unit | D6: Plot A/B | E6: Plot C/D | F6: Total qty | G6: Supply rate £ | H6: Install rate £ | I6: Supply £ | J6: Install £ | K6: Line total £ | L6: Notes
A7: 4A Internal doorsets (NRM2 24 / package JOI)
B8: Leaves from the plan door gaps: 910 -> 826 x 2040; 810 -> 726; 610 -> 526; 1,210 -> pair (cupboard, confirm). Linings 32 mm x (wall + 13). Internal doors non-rated (FF floor below 4.5 m, ADB Vol 1) except the under-stair store door.
A9: 4A.1 | B9: ID01 GF Hall / Bedroom 1: 1 x leaf 826 x 2040 x 35, 32 x 132 lining set (partition 119), non-rated | C9: nr | D9: 1 | E9: 1 | F9: =D9+E9 | I9: =F9*G9 | J9: =F9*H9 | K9: =I9+J9 | L9: Gap 910 mm; wall G1
A10: 4A.2 | B10: ID02 GF Living/Kitchen / Hall: 1 x leaf 826 x 2040 x 35, 32 x 132 lining set (partition 119), non-rated | C10: nr | D10: 1 | E10: 1 | F10: =D10+E10 | I10: =F10*G10 | J10: =F10*H10 | K10: =I10+J10 | L10: Gap 910 mm; wall G2
A11: 4A.3 | B11: ID03 GF Bathroom / Hall: 1 x leaf 826 x 2040 x 35, 32 x 132 lining set (partition 119), non-rated | C11: nr | D11: 1 | E11: 1 | F11: =D11+E11 | I11: =F11*G11 | J11: =F11*H11 | K11: =I11+J11 | L11: Gap 910 mm; wall G5
A12: 4A.4 | B12: ID04 GF Hall / A/C / Laundry: 2 x leaf pair 2 x 533 x 1981 (or 2 x 526 x 2040), 32 x 132 lining set (partition 119), non-rated | C12: nr | D12: 1 | E12: 1 | F12: =D12+E12 | I12: =F12*G12 | J12: =F12*H12 | K12: =I12+J12 | L12: Gap 1210 mm; wall G6
A13: 4A.5 | B13: ID05 GF Cupboard (G8/G9, unlabelled) / Living/Kitchen: 1 x leaf 726 x 2040 x 35, 32 x 132 lining set (partition 119), non-rated | C13: nr | D13: 1 | E13: 1 | F13: =D13+E13 | I13: =F13*G13 | J13: =F13*H13 | K13: =I13+J13 | L13: Gap 810 mm; wall G8
A14: 4A.6 | B14: ID06 FF Hall + landing (incl. stair well) / Bedroom 1: 1 x leaf 826 x 2040 x 35, 32 x 132 lining set (partition 119), non-rated | C14: nr | D14: 1 | E14: 1 | F14: =D14+E14 | I14: =F14*G14 | J14: =F14*H14 | K14: =I14+J14 | L14: Gap 910 mm; wall F1
A15: 4A.7 | B15: ID07 FF Living/Kitchen / Hall + landing (incl. stair well): 1 x leaf 826 x 2040 x 35, 32 x 132 lining set (partition 119), non-rated | C15: nr | D15: 1 | E15: 1 | F15: =D15+E15 | I15: =F15*G15 | J15: =F15*H15 | K15: =I15+J15 | L15: Gap 910 mm; wall F2
A16: 4A.8 | B16: ID08 FF Bathroom / Hall + landing (incl. stair well): 1 x leaf 826 x 2040 x 35, 32 x 132 lining set (partition 119), non-rated | C16: nr | D16: 1 | E16: 1 | F16: =D16+E16 | I16: =F16*G16 | J16: =F16*H16 | K16: =I16+J16 | L16: Gap 910 mm; wall F3
A17: 4A.9 | B17: ID09 FF Cupboard (F6/F7, unlabelled) / Living/Kitchen: 1 x leaf 726 x 2040 x 35, 32 x 132 lining set (partition 119), non-rated | C17: nr | D17: 1 | E17: 1 | F17: =D17+E17 | I17: =F17*G17 | J17: =F17*H17 | K17: =I17+J17 | L17: Gap 810 mm; wall F6
A18: 4A.10 | B18: ID10 FF Hall + landing (incl. stair well) / Store: 1 x leaf 526 x 2040 x 35, 32 x 132 lining set (partition 119), non-rated | C18: nr | D18: 1 | E18: 1 | F18: =D18+E18 | I18: =F18*G18 | J18: =F18*H18 | K18: =I18+J18 | L18: Gap 610 mm; wall F8
A19: 4A.11 | B19: ID11 FF A/C / Laundry / Hall + landing (incl. stair well): 2 x leaf pair 2 x 533 x 1981 (or 2 x 526 x 2040), 32 x 132 lining set (partition 119), non-rated | C19: nr | D19: 1 | E19: 1 | F19: =D19+E19 | I19: =F19*G19 | J19: =F19*H19 | K19: =I19+J19 | L19: Gap 1210 mm; wall F9
A20: 4A.12 | B20: ID12 GF Hall / Store (under stair, via W_c): 1 x leaf 826 x 2040 x 35, ICF reveal: 32 x 315 lining (6in Std 285.75 + boards), FD30S self-closing (confirm with BCO) | C20: nr | D20: 1 | E20: 1 | F20: =D20+E20 | I20: =F20*G20 | J20: =F20*H20 | K20: =I20+J20 | L20: Gap 900 mm; wall W_c (ICF 6in Std)
A21: 4B Ironmongery (NRM2 24 / package JOI)
A22: 4B.1 | B22: Butt hinges, pairs (1.5 pair per leaf) | C22: pr | D22: 21 | E22: 21 | F22: =D22+E22 | I22: =F22*G22 | J22: =F22*H22 | K22: =I22+J22 | L22: 14 leaves per plot
A23: 4B.2 | B23: Standard sets: tubular latch and lever pair | C23: set | D23: 4 | E23: 4 | F23: =D23+E23 | I23: =F23*G23 | J23: =F23*H23 | K23: =I23+J23
A24: 4B.3 | B24: Bathroom sets: privacy lock, lever pair, emergency release | C24: set | D24: 2 | E24: 2 | F24: =D24+E24 | I24: =F24*G24 | J24: =F24*H24 | K24: =I24+J24
A25: 4B.4 | B25: Cupboard sets per leaf: catch and pull | C25: set | D25: 7 | E25: 7 | F25: =D25+E25 | I25: =F25*G25 | J25: =F25*H25 | K25: =I25+J25 | L25: Per leaf; 5 doorsets
A26: 4B.5 | B26: Flush bolts to cupboard double doors (fixed leaf) | C26: set | D26: 2 | E26: 2 | F26: =D26+E26 | I26: =F26*G26 | J26: =F26*H26 | K26: =I26+J26 | L26: One per double door
A27: 4B.6 | B27: FD30S sets: rated hinges, overhead closer, intumescent and smoke seals, signage | C27: set | D27: 1 | E27: 1 | F27: =D27+E27 | I27: =F27*G27 | J27: =F27*H27 | K27: =I27+J27 | L27: Under-stair store - precaution, confirm with Building Control
A28: 4C External doorsets (for information - supply by others)
A29: 4C.1 | B29: GF flat entrance door (XD02), 1040 x 2100 structural opening, Front elevation; PAS 24 / SBD external doorset | C29: nr | D29: 1 | E29: 1 | F29: =D29+E29 | I29: =F29*G29 | J29: =F29*H29 | K29: =I29+J29 | L29: Window / door package - coordination only
A30: 4C.2 | B30: FF flat entrance door, stair lobby (WG01), 1040 x 2100 structural opening, Stair-lobby front elevation; PAS 24 / SBD external doorset | C30: nr | D30: 1 | E30: 1 | F30: =D30+E30 | I30: =F30*G30 | J30: =F30*H30 | K30: =I30+J30 | L30: Window / door package - coordination only
A31: 4C.3 | B31: GF rear door, living/kitchen, 1040 x 2100 structural opening, Rear elevation; PAS 24 / SBD external doorset | C31: nr | D31: 1 | E31: 1 | F31: =D31+E31 | I31: =F31*G31 | J31: =F31*H31 | K31: =I31+J31 | L31: Window / door package - coordination only
A33: PACKAGE SUMMARY - Bill 4 Internal Doors & Ironmongery (package JOI; amounts by others, excl. VAT)
A34: Section | B34: Description | I34: Supply £ | J34: Install £ | K34: Total £
A35: 4A | B35: Internal doorsets (NRM2 24 / package JOI) | I35: =SUM(I8:I20) | J35: =SUM(J8:J20) | K35: =SUM(K8:K20)
A36: 4B | B36: Ironmongery (NRM2 24 / package JOI) | I36: =SUM(I22:I27) | J36: =SUM(J22:J27) | K36: =SUM(K22:K27)
A37: 4C | B37: External doorsets (for information - supply by others) | I37: =SUM(I29:I31) | J37: =SUM(J29:J31) | K37: =SUM(K29:K31)
A38: PACKAGE TOTAL - Bill 4, carried to the Cover overview | I38: =SUM(I35:I37) | J38: =SUM(J35:J37) | K38: =SUM(K35:K37)
A39: Pale-yellow cells are the only inputs (Supply rate, Install rate). Amounts, subtotals and totals are formulas; the sheet is protected without a password (Review > Unprotect Sheet). Amounts exclude VAT and are NOT part of the Nudura ICF price.

Sheet Bill 5 Joinery
C1: Bill 5 - Joinery - Skirtings, Architraves & Window Boards
C2: Second-fix joinery measured per room and per opening. [NRM2 22 / package JOI]
A4: DISCLAIMER: This information is supplied in good faith for guidance and coordination only. It is not part of the Nudura ICF price and must be checked and verified by the appropriate professional (quantity surveyor, designer, engineer or supplier) before use. Only the Nudura ICF formwork and associated accessories are included in our price. Quantities are measured from the quotation model and drawings; no allowance for waste is included unless stated. Plot C/D is the handed mirror of Plot A/B; quantities match except Bill 6. Rates and amounts are by others.
A6: Ref | B6: Description | C6: Unit | D6: Plot A/B | E6: Plot C/D | F6: Total qty | G6: Supply rate £ | H6: Install rate £ | I6: Supply £ | J6: Install £ | K6: Line total £ | L6: Notes
A7: 5A Skirtings (NRM2 22 / package JOI)
B8: Room floor perimeter on walls less every door width opening into the room; stair-well balustrade edge excluded.
A9: 5A.1 | B9: Skirting: GF GF flat, Living/Kitchen | C9: m | D9: 17.35 | E9: 17.35 | F9: =D9+E9 | I9: =F9*G9 | J9: =F9*H9 | K9: =I9+J9
A10: 5A.2 | B10: Skirting: GF GF flat, Cupboard (G8/G9, unlabelled) | C10: m | D10: 2.59 | E10: 2.59 | F10: =D10+E10 | I10: =F10*G10 | J10: =F10*H10 | K10: =I10+J10
A11: 5A.3 | B11: Skirting: GF GF flat, Bathroom | C11: m | D11: 7.81 | E11: 7.81 | F11: =D11+E11 | I11: =F11*G11 | J11: =F11*H11 | K11: =I11+J11
A12: 5A.4 | B12: Skirting: GF GF flat, Hall | C12: m | D12: 5.45 | E12: 5.45 | F12: =D12+E12 | I12: =F12*G12 | J12: =F12*H12 | K12: =I12+J12
A13: 5A.5 | B13: Skirting: GF GF flat, Bedroom 1 | C13: m | D13: 14.24 | E13: 14.24 | F13: =D13+E13 | I13: =F13*G13 | J13: =F13*H13 | K13: =I13+J13
A14: 5A.6 | B14: Skirting: GF GF flat, A/C / Laundry | C14: m | D14: 2.92 | E14: 2.92 | F14: =D14+E14 | I14: =F14*G14 | J14: =F14*H14 | K14: =I14+J14
A15: 5A.7 | B15: Skirting: GF GF flat, Store (under stair, via W_c) | C15: m | D15: 7.2 | E15: 7.2 | F15: =D15+E15 | I15: =F15*G15 | J15: =F15*H15 | K15: =I15+J15
A16: 5A.8 | B16: Skirting: GF FF flat, Stairs / entrance lobby (FF flat) | C16: m | D16: 6.56 | E16: 6.56 | F16: =D16+E16 | I16: =F16*G16 | J16: =F16*H16 | K16: =I16+J16
A17: 5A.9 | B17: Skirting: FF FF flat, Living/Kitchen | C17: m | D17: 18.39 | E17: 18.39 | F17: =D17+E17 | I17: =F17*G17 | J17: =F17*H17 | K17: =I17+J17
A18: 5A.10 | B18: Skirting: FF FF flat, Cupboard (F6/F7, unlabelled) | C18: m | D18: 2.59 | E18: 2.59 | F18: =D18+E18 | I18: =F18*G18 | J18: =F18*H18 | K18: =I18+J18
A19: 5A.11 | B19: Skirting: FF FF flat, Bathroom | C19: m | D19: 7.81 | E19: 7.81 | F19: =D19+E19 | I19: =F19*G19 | J19: =F19*H19 | K19: =I19+J19
A20: 5A.12 | B20: Skirting: FF FF flat, Hall + landing (incl. stair well) | C20: m | D20: 8.7 | E20: 8.7 | F20: =D20+E20 | I20: =F20*G20 | J20: =F20*H20 | K20: =I20+J20
... A23: 5A.15 | B23: Skirting: FF FF flat, Store | C23: m | D23: 3.66 | E23: 3.66 | F23: =D23+E23 | I23: =F23*G23 | J23: =F23*H23 | K23: =I23+J23
A24: 5A.T | B24: Skirtings - total | C24: m | D24: =SUM(D9:D23) | E24: =SUM(E9:E23) | F24: =D24+E24 | K24: not priced | L24: Order guide +10% = 268.9
A25: 5B Architraves (NRM2 22 / package JOI)
B26: Per face = 2 legs x 2150 + (door gap + 2 x 70). Internal doors both faces; external doors inside face only.
A27: 5B.1 | B27: Architrave to internal doors both faces | C27: m | D27: 128.58 | E27: 128.58 | F27: =D27+E27 | I27: =F27*G27 | J27: =F27*H27 | K27: =I27+J27 | L27: Order guide +10% = 282.9
A28: 5B.2 | B28: Architrave to external doors one face | C28: m | D28: 16.44 | E28: 16.44 | F28: =D28+E28 | I28: =F28*G28 | J28: =F28*H28 | K28: =I28+J28 | L28: Order guide +10% = 36.2
A29: 5C Window boards (NRM2 22 / package JOI)
B30: Length = structural opening width + 2 x 50 horns; depth = internal reveal 195 + 25 nosing = 220 mm (order 225 mm MDF / uPVC).
A31: 5C.1 | B31: Window board 220 x 1680 mm long, with horns, nosing to front edge | C31: nr | D31: 2 | E31: 2 | F31: =D31+E31 | I31: =F31*G31 | J31: =F31*H31 | K31: =I31+J31
A32: 5C.2 | B32: Window board 220 x 1670 mm long, with horns, nosing to front edge | C32: nr | D32: 2 | E32: 2 | F32: =D32+E32 | I32: =F32*G32 | J32: =F32*H32 | K32: =I32+J32
A33: 5C.3 | B33: Window board 220 x 1110 mm long, with horns, nosing to front edge | C33: nr | D33: 2 | E33: 2 | F33: =D33+E33 | I33: =F33*G33 | J33: =F33*H33 | K33: =I33+J33
A34: 5C.4 | B34: Window board 220 x 870 mm long, with horns, nosing to front edge | C34: nr | D34: 1 | E34: 1 | F34: =D34+E34 | I34: =F34*G34 | J34: =F34*H34 | K34: =I34+J34
A35: 5C.5 | B35: Window board 220 x 860 mm long, with horns, nosing to front edge | C35: nr | D35: 1 | E35: 1 | F35: =D35+E35 | I35: =F35*G35 | J35: =F35*H35 | K35: =I35+J35
A36: 5C.6 | B36: Window board 220 x 850 mm long, with horns, nosing to front edge | C36: nr | D36: 1 | E36: 1 | F36: =D36+E36 | I36: =F36*G36 | J36: =F36*H36 | K36: =I36+J36
A37: 5C.7 | B37: Window board 220 x 840 mm long, with horns, nosing to front edge | C37: nr | D37: 2 | E37: 2 | F37: =D37+E37 | I37: =F37*G37 | J37: =F37*H37 | K37: =I37+J37
A38: 5C.8 | B38: Window board 220 x 830 mm long, with horns, nosing to front edge | C38: nr | D38: 1 | E38: 1 | F38: =D38+E38 | I38: =F38*G38 | J38: =F38*H38 | K38: =I38+J38
A39: 5C.9 | B39: Window board 220 x 820 mm long, with horns, nosing to front edge | C39: nr | D39: 1 | E39: 1 | F39: =D39+E39 | I39: =F39*G39 | J39: =F39*H39 | K39: =I39+J39
A40: 5C.10 | B40: Window board 220 x 810 mm long, with horns, nosing to front edge | C40: nr | D40: 1 | E40: 1 | F40: =D40+E40 | I40: =F40*G40 | J40: =F40*H40 | K40: =I40+J40
A41: 5C.T | B41: Window boards - total length | C41: m | D41: 15.64 | E41: 15.64 | F41: =D41+E41 | K41: not priced | L41: Order guide +10% = 34.4
A43: PACKAGE SUMMARY - Bill 5 Joinery - Skirtings, Architraves & Window Boards (package JOI; amounts by others, excl. VAT)
A44: Section | B44: Description | I44: Supply £ | J44: Install £ | K44: Total £
A45: 5A | B45: Skirtings (NRM2 22 / package JOI) | I45: =SUM(I8:I24) | J45: =SUM(J8:J24) | K45: =SUM(K8:K24)
...

Sheet Bill 6 Partitions
C1: Bill 6 - Timber Stud Partitions - Framing, Openings, Pattresses & Fixings
C2: Non-loadbearing timber stud partitions and riser boxing from the TLSTF model (44 panels, GF-IN1..22 and FF-IN1..22). Linings are in Bill 3, doorsets in Bill 4. [NRM2 16 / package JOI]
A4: DISCLAIMER: This information is supplied in good faith for guidance and coordination only. It is not part of the Nudura ICF price and must be checked and verified by the appropriate professional (quantity surveyor, designer, engineer or supplier) before use. Only the Nudura ICF formwork and associated accessories are included in our price. Quantities are measured from the quotation model and drawings; no allowance for waste is included unless stated. Plot C/D is the handed mirror of Plot A/B; quantities match except Bill 6. Rates and amounts are by others.
A6: Ref | B6: Description | C6: Unit | D6: Plot A/B | E6: Plot C/D | F6: Total qty | G6: Supply rate £ | H6: Install rate £ | I6: Supply £ | J6: Install £ | K6: Line total £ | L6: Notes
A7: 6A Timber stud partitions, non-loadbearing - framing (NRM2 16 / package JOI)
B8: C16 softwood stud partitions to the TLSTF model and drawings ES26-081-TF-01 / TF-02: studs, head and bottom rails, mid-height noggins. Measured on the wall centre line, length x full height per level (GF 2,575, FF 2,450), gross - door openings NOT deducted (forming openings is measured in 6C). Rate 6A per m2 for framing LABOUR; enter a 6A Supply rate only when pricing a composite m2 rate - otherwise price timber supply in 6B, not both. Plasterboard, tape and skim are in Bill 3.
A9: 6A.1 | B9: Ground floor partitions, 2,575 high: 38 x 89 C16 studs at 600 c/c, 38 x 89 head and bottom rails (general partitions) | C9: m2 | D9: 29.01 | E9: 29.01 | F9: =D9+E9 | I9: =F9*G9 | J9: =F9*H9 | K9: =I9+J9 | L9: Length 11.26 m per plot x 2.575 m
A10: 6A.2 | B10: Ground floor partitions, 2,575 high: 38 x 89 C16 studs at 400 c/c, 38 x 89 rails (bathroom walls, pattressed) | C10: m2 | D10: 17.32 | E10: 17.32 | F10: =D10+E10 | I10: =F10*G10 | J10: =F10*H10 | K10: =I10+J10 | L10: Length 6.73 m per plot x 2.575 m
A11: 6A.3 | B11: Ground floor partitions, 2,575 high: 38 x 47 C16 studs at 600 c/c, 38 x 47 rails (riser / pipe boxing) | C11: m2 | D11: 2.56 | E11: 2.56 | F11: =D11+E11 | I11: =F11*G11 | J11: =F11*H11 | K11: =I11+J11 | L11: Length 0.99 m per plot x 2.575 m
A12: 6A.4 | B12: First floor partitions, 2,450 high: 38 x 89 C16 studs at 600 c/c, 38 x 89 head and bottom rails (general partitions) | C12: m2 | D12: 27.67 | E12: 27.67 | F12: =D12+E12 | I12: =F12*G12 | J12: =F12*H12 | K12: =I12+J12 | L12: Length 11.29 m per plot x 2.450 m
A13: 6A.5 | B13: First floor partitions, 2,450 high: 38 x 89 C16 studs at 400 c/c, 38 x 89 rails (bathroom walls, pattressed) | C13: m2 | D13: 16.48 | E13: 16.48 | F13: =D13+E13 | I13: =F13*G13 | J13: =F13*H13 | K13: =I13+J13 | L13: Length 6.73 m per plot x 2.450 m
A14: 6A.6 | B14: First floor partitions, 2,450 high: 38 x 47 C16 studs at 600 c/c, 38 x 47 rails (riser / pipe boxing) | C14: m2 | D14: 2.43 | E14: 2.43 | F14: =D14+E14 | I14: =F14*G14 | J14: =F14*H14 | K14: =I14+J14 | L14: Length 0.99 m per plot x 2.450 m
A15: 6B Partition timber - supply by section and grade (NRM2 16 / package JOI)
B16: Linear metres of C16 sawn softwood from the TLSTF model member cut lengths (pieces in Notes). Order guide in 4.8 m lengths = run x 1.05 / 4.8, not cut-optimised (as the TF sheets). Door-gap bottom-rail pieces cut out on site are not measured. Supply only - framing labour is in 6A / 6C.
A17: 6B.1 | B17: 38 x 89 C16 kiln-dried sawn softwood: studs, king studs and cripple / board-support studs | C17: m | D17: 256.02 | E17: 258.26 | F17: =D17+E17 | I17: =F17*G17 | J17: =F17*H17 | K17: =I17+J17 | L17: 139 / 140 pieces (A/B / C/D)
A18: 6B.2 | B18: 38 x 89 C16 kiln-dried sawn softwood: head and bottom rails, incl. door head rails | C18: m | D18: 71.97 | E18: 71.97 | F18: =D18+E18 | I18: =F18*G18 | J18: =F18*H18 | K18: =I18+J18 | L18: 58 / 58 pieces (A/B / C/D)
A19: 6B.3 | B19: 38 x 89 C16 kiln-dried sawn softwood: noggins (mid-height, fixing and board support) | C19: m | D19: 21.11 | E19: 21.07 | F19: =D19+E19 | I19: =F19*G19 | J19: =F19*H19 | K19: =I19+J19 | L19: 69 / 70 pieces (A/B / C/D)
A20: 6B.4 | B20: 38 x 47 C16 kiln-dried sawn softwood: studs (riser boxing) | C20: m | D20: 24.32 | E20: 24.32 | F20: =D20+E20 | I20: =F20*G20 | J20: =F20*H20 | K20: =I20+J20 | L20: 10 / 10 pieces (A/B / C/D)
A21: 6B.5 | B21: 38 x 47 C16 kiln-dried sawn softwood: head and bottom rails (riser boxing) | C21: m | D21: 3.95 | E21: 3.95 | F21: =D21+E21 | I21: =F21*G21 | J21: =F21*H21 | K21: =I21+J21 | L21: 8 / 8 pieces (A/B / C/D)
A22: 6B.6 | B22: 38 x 47 C16 kiln-dried sawn softwood: noggins (riser boxing) | C22: m | D22: 1.58 | E22: 1.58 | F22: =D22+E22 | I22: =F22*G22 | J22: =F22*H22 | K22: =I22+J22 | L22: 6 / 6 pieces (A/B / C/D)
A23: 6B.7 | B23: 38 x 89 C16 - 4.8 m lengths to order (run +5%, not cut-optimised) | C23: nr | D23: 77 | E23: 77 | F23: =D23+E23 | K23: not priced | L23: Ordering guide only - not priced in addition to the runs above
A24: 6B.8 | B24: 38 x 47 C16 - 4.8 m lengths to order (run +5%, not cut-optimised) | C24: nr | D24: 7 | E24: 7 | F24: =D24+E24 | K24: not priced | L24: Ordering guide only - not priced in addition to the runs above
A25: 6C Forming door openings in partitions (NRM2 16 / package JOI)
B26: Per opening, from the TLSTF model: 2 full-height king studs, 38 x 89 head rail at 2,100 above the bottom rail, cripple studs over the head (2 board-support cripples at the jambs plus intermediates on the stud grid) and the bottom rail cut out across the gap. Timber is in 6B; the rate is per opening (labour; supply only for extra fixings / packers).
A27: 6C.1 | B27: Form door opening 610 wide x 2,100 high in 89 partition (cupboard): 2 king studs, head rail 610, 4 cripple studs over | C27: nr | D27: 1 | E27: 1 | F27: =D27+E27 | I27: =F27*G27 | J27: =F27*H27 | K27: =I27+J27 | L27: GF 0 / FF 2 (both plots); doorsets in Bill 4
A28: 6C.2 | B28: Form door opening 810 wide x 2,100 high in 89 partition (store / cupboard): 2 king studs, head rail 810, 3 cripple studs over | C28: nr | D28: 2 | E28: 2 | F28: =D28+E28 | I28: =F28*G28 | J28: =F28*H28 | K28: =I28+J28 | L28: GF 2 / FF 2 (both plots); doorsets in Bill 4
A29: 6C.3 | B29: Form door opening 910 wide x 2,100 high in 89 partition (room door): 2 king studs, head rail 910, 3 or 4 cripple studs over | C29: nr | D29: 6 | E29: 6 | F29: =D29+E29 | I29: =F29*G29 | J29: =F29*H29 | K29: =I29+J29 | L29: GF 6 / FF 6 (both plots); doorsets in Bill 4
A30: 6C.4 | B30: Form door opening 1,210 wide x 2,100 high in 89 partition (cupboard pair): 2 king studs, head rail 1,210, 3 or 4 cripple studs over | C30: nr | D30: 2 | E30: 2 | F30: =D30+E30 | I30: =F30*G30 | J30: =F30*H30 | K30: =I30+J30 | L30: GF 2 / FF 2 (both plots); doorsets in Bill 4
A31: 6D Pattresses, noggins to floor and roof structure, head restraint (NRM2 16 / package JOI)
B32: From the LEP2 build reports and the TLSTF extract. Pattress: 18 mm WBP plywood between studs on the bathroom face of the 400 c/c walls for sanitaryware and fittings. Floor noggins between the PS10 metal-web joists where a partition runs parallel to them (GF head fixing and FF bottom-rail support). Ceiling noggins between truss bottom chords where an FF partition runs parallel; slotted head-restraint clips allow truss deflection.
A33: 6D.1 | B33: 18 mm WBP plywood pattress boards between studs, bathroom face, cut to fit (bands 150-1,950 above floor) | C33: m2 | D33: 16.66 | E33: 16.68 | F33: =D33+E33 | I33: =F33*G33 | J33: =F33*H33 | K33: =I33+J33 | L33: 54 / 58 pieces (A/B / C/D); handed walls differ slightly
A34: 6D.2 | B34: Noggins 47 x 250 C24 x 301 long between floor joists over partitions, skew-nailed or on hangers | C34: nr | D34: 15 | E34: 15 | F34: =D34+E34 | I34: =F34*G34 | J34: =F34*H34 | K34: =I34+J34 | L34: 9.03 m in total; at max 600 c/c plus ends and door jambs
A35: 6D.3 | B35: Noggins 47 x 72 C24 x 528 long between truss bottom chords over FF partitions | C35: nr | D35: 31 | E35: 31 | F35: =D35+E35 | I35: =F35*G35 | J35: =F35*H35 | K35: =I35+J35 | L35: 32.74 m in total
A36: 6D.4 | B36: Partition head-restraint clip, slotted (Simpson Strong-Tie STC or UK equivalent - confirm), FF head rail to truss chord / noggin | C36: nr | D36: 45 | E36: 45 | F36: =D36+E36 | I36: =F36*G36 | J36: =F36*H36 | K36: =I36+J36 | L36: 5 mm deflection gap kept at the head
A37: 6E Fixings and sundries (NRM2 16 / package JOI)
B38: Bottom rail fixings measured along the rail length (door gaps excluded). Fixing types are proposals - confirm with the designer.
A39: 6E.1 | B39: Fix GF bottom rails to the ground-bearing slab / screed: concrete screws or shot-fired fixings at max 600 c/c, on DPC strip (confirm) | C39: m | D39: 14.22 | E39: 14.22 | F39: =D39+E39 | I39: =F39*G39 | J39: =F39*H39 | K39: =I39+J39 | L39: GF bottom rail length
A40: 6E.2 | B40: Fix FF bottom rails through the deck into joists / floor noggins | C40: m | D40: 13.64 | E40: 13.64 | F40: =D40+E40 | I40: =F40*G40 | J40: =F40*H40 | K40: =I40+J40 | L40: FF bottom rail length
